File: examples/IronOxide_14nm_MvsH.dat
[Header]
; MPMS3 Data File (default extension .dat)
; Copyright (c) 2007, Quantum Design, Inc. All rights reserved.
TITLE,
FILEOPENTIME,3823624112.20733,02/27/2021,9:48 pm
BYAPP,MPMS3 w/ AC,1.0,1.1
INFO,MPMS3 Measurement Release 1.1.16 Build 424, MultiVu Release 2.3.4.19,APPNAME
INFO,Linear Motor Servo Controller,MOTOR_MODULE_NAME
INFO,3101-100 J0,MOTOR_HW_VERSION
INFO,MMC721,MOTOR_SERIAL_NUMBER
INFO,01.04.28,MOTOR_SOFTWARE_VERSION
INFO,Quantum Design Squid Module,SQUID_MODULE_NAME
INFO,3101-501 B0,SQUID_HW_VERSION
INFO,SQM195,SQUID_SERIAL_NUMBER
INFO,01.03.04,SQUID_SOFTWARE_VERSION
INFO,SQUID AC,AC_MODULE_NAME
INFO,3101-401 f1,AC_HW_VERSION
INFO,SAC107,AC_SERIAL_NUMBER
INFO,SQUID AC 00.95.07,AC_SOFTWARE_VERSION
INFO,TCI166,COIL_SERIAL_NUMBER
INFO,0,MOMENT_UNITS
INFO,KMK159,SAMPLE_MATERIAL
INFO,,SAMPLE_COMMENT
INFO,0.6,SAMPLE_MASS
INFO,,SAMPLE_VOLUME
INFO,,SAMPLE_MOLECULAR_WEIGHT
INFO,,SAMPLE_SIZE
INFO,,SAMPLE_SHAPE
INFO,Standard,SAMPLE_HOLDER
INFO,Standard,SAMPLE_HOLDER_DETAIL
INFO,67.29,SAMPLE_OFFSET
DATATYPE,COMMENT,1
DATATYPE,TIME,2
STARTUPAXIS,X,2
STARTUPAXIS,Y1,5
FIELDGROUP, VSM,2,3,4,5,6,8,9,10,11,14,15
FIELDGROUP, DC, 2,3,4,14,56,57,58,59,60,61,62,63,64,65,66,67,68,69
FIELDGROUP, AC, 2,3,4,11,16,17,18,19,20,21,22,23,24,25,26,27,28,29,30
STARTUPGROUP, All
[Data]
Comment,Time Stamp (sec),Temperature (K),Magnetic Field (Oe),Moment (emu),M. Std. Err. (emu),Transport Action,Averaging Time (sec),Frequency (Hz),Peak Amplitude (mm),Center Position (mm),Lockin Signal' (V),Lockin Signal (V),Range,M. Quad. Signal (emu),AC Moment (emu),AC M. Std Err. (emu),AC Phase (deg),AC Phase Std. Err. (deg),AC Susceptibility (emu/Oe),AC Suscept. Std Err. (emu/Oe),AC X' (emu/Oe),AC X' Std Err. (emu/Oe),AC X'' (emu/Oe),AC X'' Std Err. (emu/Oe),AC Drive (Oe),AC Frequency (Hz),AC Averaging Time (sec),AC Cycles,AC Range,AC Measure Type,AC Signal' (V),AC Signal'' (V),AC Trim Coil Ratio,AC Trim Coil Phase,Min. Temperature (K),Max. Temperature (K),Min. Field (Oe),Max. Field (Oe),Mass (grams),Motor Lag (deg),Pressure (Torr),Measure Count,Measurement Number,SQUID Status (code),Motor Status (code),Measure Status (code),Motor Current (amps),Motor Temp. (C),Temp. Status (code),Field Status (code),Chamber Status (code),Chamber Temp (K),Redirection State,Evercool Status,Average Temp (K),Rotation Angle (deg),Rotator state,DC Moment Fixed Ctr (emu),DC Moment Err Fixed Ctr (emu),DC Moment Free Ctr (emu),DC Moment Err Free Ctr (emu),DC Fixed Fit,DC Free Fit,DC Calculated Center (mm),DC Calculated Center Err (mm),DC Scan Length (mm),DC Scan Time (s),DC Number of Points,DC Squid Drift,DC Min V (V),DC Max V (V),DC Scans per Measure,Map 01,Map 02,Map 03,Map 04,Map 05,Map 06,Map 07,Map 08,Map 09,Map 10,Map 11,Map 12,Map 13,Map 14,Map 15,Map 16
,3823625115.80604,5.00273561477661,-70000.3359375,,,6,,,,31.4133701324463,,,100,,,,,,,,,,,,,,,,,,,,,,4.99636268615723,5.00259399414063,-70000.3359375,-70000.3359375,,,3.92370247840881,,1,0,0,0,0.013885498046875,31.2805480957031,1,1,1,5.00300598144531,0,4232056832,4.99982497566625,,,-0.0432166903777341,0.00225557855566332,-0.0452427160304751,0.00225734907267124,0.705365300178528,0.972612500190735,30.2790298461914,0,35,4,200,-0.00217400467954576,-4.49542665481567,4.50534343719482,1,,,,,,,,,,,,,,,,
,3823625211.45535,5.00280547142029,-55000.33203125,,,6,,,,31.4133701324463,,,100,,,,,,,,,,,,,,,,,,,,,,4.99718809127808,5.00304841995239,-55000.33203125,-55000.33203125,,,3.93287038803101,,1,0,0,0,0.013885498046875,31.2805480957031,1,1,1,5.00324630737305,0,4232058368,5.00026216506958,,,-0.0431744720163745,0.00225620945344142,-0.0452616513966731,0.00225807617866912,0.701498448848724,0.976375937461853,30.2614822387695,5.50104379653931,35,4,200,0.00204447680152953,-0.481445282697678,1.83253467082977,1,,,,,,,,,,,,,,,,
,3823625304.34308,5.00199842453003,-40000.30078125,,,6,,,,31.4133701324463,,,100,,,,,,,,,,,,,,,,,,,,,,4.9964165687561,5.00187683105469,-40000.30078125,-40000.30078125,,,3.93226790428162,,1,0,0,0,0.013885498046875,31.2805480957031,1,1,1,5.00221014022827,0,4232058240,4.99914150238037,,,-0.0431036819151367,0.00225456589062236,-0.0452331671792844,0.00225646495321848,0.698730230331421,0.980264067649841,30.2484111785889,0,35,4,200,0.00260095740668476,-0.468935012817383,1.83694863319397,1,,,,,,,,,,,,,,,,
,3823625394.29934,5.00232005119324,-25000.416015625,,,6,,,,31.4133701324463,,,100,,,,,,,,,,,,,,,,,,,,,,4.99667453765869,5.00294637680054,-25000.416015625,-25000.416015625,,,3.92047810554504,,1,0,0,0,0.013885498046875,31.7693061828613,1,1,1,5.00311422348022,0,4232058016,4.99975423812866,,,-0.0429732636846448,0.00224905089756755,-0.0451284833529693,0.00225109886628162,0.696982443332672,0.983823597431183,30.2394771575928,,35,4,200,0.00267341476865113,-0.460140287876129,1.83722102642059,1,,,,,,,,,,,,,,,,
,3823625486.99445,5.00303030014038,-10000.2490234375,,,6,,,,31.4133701324463,,,100,,,,,,,,,,,,,,,,,,,,,,4.99727296829224,5.00298833847046,-10000.2490234375,-10000.2490234375,,,3.90846061706543,,1,0,0,0,0.013885498046875,31.7693061828613,1,1,1,5.00311613082886,0,4232057920,5.00035605430603,,,-0.0426387658945963,0.00223194812573439,-0.0447846087988828,0.00223384278065915,0.696440935134888,0.986974060535431,30.235990524292,0.000881589716300368,35,4,200,0.00241628778167069,-0.442294806241989,1.81530499458313,1,,,,,,,,,,,,,,,,
,3823625566.69617,5.00261855125427,-8500.3447265625,,,6,,,,31.4133701324463,,,100,,,,,,,,,,,,,,,,,,,,,,4.99723815917969,5.00261497497559,-8500.3447265625,-8500.3447265625,,,3.90588688850403,,1,0,0,0,0.013885498046875,31.7693061828613,1,1,1,5.00283718109131,0,4232058528,5.00012230873108,,,-0.0425554603836153,0.0022274307435677,-0.0446957933353863,0.00222940284475993,0.696651995182037,0.987332165241241,30.2368297576904,0.00017467858560849,35,4,200,0.00304205948486924,-0.439410954713821,1.82107102870941,1,,,,,,,,,,,,,,,,
,3823625636.10071,5.0027801990509,-7000.35546875,,,6,,,,31.4133701324463,,,100,,,,,,,,,,,,,,,,,,,,,,4.99721622467041,5.00276517868042,-7000.35546875,-7000.35546875,,,3.89919137954712,,1,0,0,0,0.013885498046875,31.2805480957031,1,1,1,5.00311374664307,0,4232058304,5.0001452922821,,,-0.0424372581089061,0.00222095942714359,-0.0445648142370157,0.00222286233227852,0.697034358978271,0.987563908100128,30.2381782531738,0,35,4,200,0.00251591484993696,-0.43846008181572,1.80776476860046,1,,,,,,,,,,,,,,,,
,3823625705.54962,5.00230145454407,-5500.365234375,,,6,,,,31.4133701324463,,,100,,,,,,,,,,,,,,,,,,,,,,4.99671363830566,5.00231981277466,-5500.365234375,-5500.365234375,,,3.89532017707825,,1,0,0,0,0.013885498046875,31.2805480957031,1,1,1,5.00228309631348,0,4232058336,4.99961185455322,,,-0.0422388382037535,0.00221013374422324,-0.0443481495267816,0.00221204752466769,0.697633922100067,0.987856268882751,30.2404441833496,0,35,4,200,0.00223062094300985,-0.440794765949249,1.79635751247406,1,,,,,,,,,,,,,,,,
,3823625775.63529,5.002760887146,-4000.44946289063,,,6,,,,31.4133701324463,,,100,,,,,,,,,,,,,,,,,,,,,,4.9974193572998,5.00280666351318,-4000.44946289063,-4000.44946289063,,,3.89014077186584,,1,0,0,0,0.013885498046875,31.2805480957031,1,1,1,5.00309944152832,0,4232058464,5.00027599334717,,,-0.0418207352766913,0.00218744634781681,-0.043892171516206,0.00218929400559259,0.698749482631683,0.988232553005219,30.2447032928467,,35,4,200,0.00188637454994023,-0.43218395113945,1.78458404541016,1,,,,,,,,,,,,,,,,
,3823625843.41903,5.003009557724,-2500.28833007813,,,6,,,,31.4133701324463,,,100,,,,,,,,,,,,,,,,,,,,,,4.99733018875122,5.00310277938843,-2500.28833007813,-2500.28833007813,,,3.88592839241028,,1,0,0,0,0.013885498046875,31.2805480957031,1,1,1,5.00320053100586,0,4232058400,5.00029911994934,,,-0.0404587385128737,0.00211457212293242,-0.0424294836942556,0.00211631983431478,0.701091647148132,0.988903343677521,30.2538433074951,0,35,4,200,0.00161966041196138,-0.41248419880867,1.72341597080231,1,,,,,,,,,,,,,,,,
,3823625913.88934,5.00289988517761,-1000.26202392578,,,6,,,,31.4133701324463,,,100,,,,,,,,,,,,,,,,,,,,,,4.99749517440796,5.00326251983643,-1000.26202392578,-1000.26202392578,,,3.88204312324524,,1,0,0,0,0.013885498046875,31.2805480957031,1,1,1,5.00324153900146,0,4232058368,5.00040330886841,,,-0.0323552775464813,0.00168887956353044,-0.0338871544260495,0.0016902258220794,0.705028891563416,0.989801824092865,30.2694091796875,0,35,4,200,0.00117859663441777,-0.331345021724701,1.37196791172028,1,,,,,,,,,,,,,,,,
,3823625994.24342,5.00299000740051,-400.400573730469,,,6,,,,31.4133701324463,,,100,,,,,,,,,,,,,,,,,,,,,,4.99746608734131,5.00296068191528,-400.400573730469,-400.400573730469,,,3.87605738639832,,1,0,0,0,0.013885498046875,31.2805480957031,1,1,1,5.00322723388672,0,4232058336,5.00021902720134,,,-0.0215677567758219,0.00112513813075306,-0.0225758334280602,0.00112603516186727,0.706836521625519,0.990144610404968,30.2765254974365,0.000131108303321525,35,4,200,0.00128693412989378,-0.226051032543182,0.910696864128113,1,,,,,,,,,,,,,,,,
,3823626062.43824,5.00305604934692,200.230850219727,,,6,,,,31.4133701324463,,,100,,,,,,,,,,,,,,,,,,,,,,4.99768924713135,5.00311708450317,200.230850219727,200.230850219727,,,3.87436604499817,,1,0,0,0,0.013885498046875,31.2805480957031,1,1,1,5.00331830978394,0,4232058336,5.00048580169678,,,0.0059375744917077,0.000313348771839647,0.00628856944961318,0.000313659981468747,0.673158288002014,0.990362405776978,30.1400699615479,5.48999738693237,35,4,200,0.000975445262156427,-0.251395702362061,0.0681371837854385,1,,,,,,,,,,,,,,,,
,3823626129.38902,5.00295352935791,800.202270507812,,,6,,,,31.4133701324463,,,100,,,,,,,,,,,,,,,,,,,,,,4.99732637405396,5.00278902053833,800.202270507812,800.202270507812,,,3.87036681175232,,1,0,0,0,0.013885498046875,31.2805480957031,1,1,1,5.00327396392822,0,4232058592,5.00019311904907,,,0.026139035078158,0.00136649191597972,0.0274208006177612,0.00136768785108638,0.700341761112213,0.990462839603424,30.2503604888916,0,35,4,200,0.00108425319194794,-1.11045587062836,0.272983342409134,1,,,,,,,,,,,,,,,,
,3823626211.05833,5.00295257568359,2000.20629882813,,,6,,,,31.4133701324463,,,100,,,,,,,,,,,,,,,,,,,,,,4.99738168716431,5.00307750701904,2000.20629882813,2000.20629882813,,,3.86302757263184,,1,0,0,0,0.013885498046875,31.7693061828613,1,1,1,5.00322818756103,0,4232058368,5.00035991668701,,,0.0390642908988497,0.00204139502224936,0.0409619038554818,0.00204309437437511,0.701535701751709,0.990098476409912,30.2553558349609,0.239734217524529,35,4,200,0.000663503131363541,-1.65712106227875,0.408251583576202,1,,,,,,,,,,,,,,,,
,3823626286.63368,5.0028281211853,3500.31811523438,,,6,,,,31.4133701324463,,,100,,,,,,,,,,,,,,,,,,,,,,4.99723339080811,5.00292301177978,3500.31811523438,3500.31811523438,,,3.86158728599548,,1,0,0,0,0.013885498046875,31.7693061828613,1,1,1,5.00313282012939,0,4232058304,5.00041408538818,,,0.0416327659194971,0.00217757665876325,0.0436964545495763,0.00217949425546324,0.698803007602692,0.989837348461151,30.2445278167725,,35,4,200,0.000792510574683547,-1.76346039772034,0.434475034475327,1,,,,,,,,,,,,,,,,
,3823626362.63284,5.00293636322022,5000.39306640625,,,6,,,,31.4133701324463,,,100,,,,,,,,,,,,,,,,,,,,,,4.99741649627686,5.00295495986938,5000.39306640625,5000.39306640625,,,3.85810542106628,,1,0,0,0,0.013885498046875,32.7468223571777,1,1,1,5.0032377243042,0,4232058432,5.00037612915039,,,0.0422319067438825,0.00221000161534287,0.0443455533076847,0.00221187657971702,0.697321534156799,0.989540576934814,30.2387084960937,5.49897336959839,35,4,200,0.00124581507407129,-1.79014098644257,0.442127406597137,1,,,,,,,,,,,,,,,,
,3823626438.89869,5.00292801856995,6500.27294921875,,,6,,,,31.4133701324463,,,100,,,,,,,,,,,,,,,,,,,,,,4.99735307693481,5.00305795669556,6500.27294921875,6500.27294921875,,,3.85442113876343,,1,0,0,0,0.013885498046875,31.7693061828613,1,1,1,5.00329351425171,0,4232058400,5.00044894218445,,,0.0424812404625247,0.00222357162921116,0.0446184479582109,0.00222549462102102,0.696617484092712,0.989265501499176,30.235990524292,0.17548394203186,35,4,200,0.00178332685027271,-1.80437326431274,0.44445613026619,1,,,,,,,,,,,,,,,,
,3823626514.15465,5.00289940834045,8000.43408203125,,,6,,,,31.4133701324463,,,100,,,,,,,,,,,,,,,,,,,,,,4.9972620010376,5.00290536880493,8000.43408203125,8000.43408203125,,,3.85179924964905,,1,0,0,0,0.013885498046875,31.2805480957031,1,1,1,5.00333309173584,0,4232058560,5.0003161907196,,,0.0426198767653209,0.00223111885610092,0.0447693340692034,0.00223302815112289,0.696227133274078,0.988931655883789,30.2345237731934,4.98244428634644,35,4,200,0.00196271855384111,-1.80816459655762,0.449375122785568,1,,,,,,,,,,,,,,,,
,3823626591.14828,5.00299692153931,9500.2646484375,,,6,,,,31.4133701324463,,,100,,,,,,,,,,,,,,,,,,,,,,4.99733591079712,5.0029616355896,9500.2646484375,9500.2646484375,,,3.84918427467346,,1,0,0,0,0.013885498046875,31.7693061828613,1,1,1,5.00328779220581,0,4232058368,5.00034675598145,,,0.0427109511232655,0.00223606970795156,0.0448703453345779,0.00223807253527243,0.695981800556183,0.988668560981751,30.2337074279785,,35,4,200,0.00201929011382163,-1.81744825839996,0.456334412097931,1,,,,,,,,,,,,,,,,
,3823626683.96908,5.00301837921143,20000.33984375,,,6,,,,31.4133701324463,,,100,,,,,,,,,,,,,,,,,,,,,,4.99717473983765,5.00303506851196,20000.33984375,20000.33984375,,,3.84404253959656,,1,0,0,0,0.013885498046875,31.2805480957031,1,1,1,5.00313329696655,0,4232058112,5.00031933784485,,,0.0430032935543719,0.00225136243116279,0.0451756343988568,0.00225335760049019,0.695998013019562,0.98659336566925,30.2346858978271,0.000184054966666736,35,4,200,0.00220406404696405,-1.82962930202484,0.461352318525314,1,,,,,,,,,,,,,,,,
,3823626772.32409,5.00322699546814,35000.19921875,,,6,,,,31.4133701324463,,,100,,,,,,,,,,,,,,,,,,,,,,4.99690818786621,5.00318145751953,35000.19921875,35000.19921875,,,3.84046697616577,,1,0,0,0,0.013885498046875,31.2805480957031,1,1,1,5.00333738327026,0,4232058304,5.00042767524719,,,0.0431712071400005,0.00225895826996831,0.0453252901030806,0.00226094389859303,0.697582840919495,0.983072757720947,30.242654800415,0,35,4,200,0.00192006723955274,-1.82975232601166,0.480245143175125,1,,,,,,,,,,,,,,,,
,3823626860.11341,5.0030255317688,50000.33984375,,,6,,,,31.4133701324463,,,100,,,,,,,,,,,,,,,,,,,,,,4.99681186676025,5.00298690795898,50000.33984375,50000.33984375,,,3.84072923660278,,1,0,0,0,0.013885498046875,31.2805480957031,1,1,1,5.00329732894897,0,4232058208,5.00032091140747,,,0.0432544129359785,0.00226171826262224,0.0453750962547404,0.00226358425509749,0.699707984924316,0.979400932788849,30.2528800964355,3.74129247665405,35,4,200,0.00196183449588716,-1.83587837219238,0.490776419639587,1,,,,,,,,,,,,,,,,
,3823626949.66977,5.00330471992493,65000.33203125,,,6,,,,31.4133701324463,,,100,,,,,,,,,,,,,,,,,,,,,,4.99667119979858,5.00352334976196,65000.33203125,65000.33203125,,,3.84179878234863,,1,0,0,0,0.013885498046875,31.7693061828613,1,1,1,5.00351762771606,0,4232058368,5.00045862197876,,,0.04330440850098,0.00226200493468885,0.0453757279492522,0.00226382892632879,0.70284378528595,0.975253283977509,30.267541885376,0.178532496094704,35,4,200,0.00219795759767294,-1.83397436141968,0.508425176143646,1,,,,,,,,,,,,,,,,
,3823627039.03502,5.0033061504364,60000.1875,,,6,,,,31.4133701324463,,,100,,,,,,,,,,,,,,,,,,,,,,4.99673652648926,5.00341892242432,60000.1875,60000.1875,,,3.83688354492188,,1,0,0,0,0.013885498046875,31.7693061828613,1,1,1,5.0035924911499,0,4232058176,5.00047383308411,,,0.0432954015452268,0.0022625162955882,0.0453877957718196,0.00226437393117783,0.701515436172485,0.976290464401245,30.2615070343018,0,35,4,200,-0.00164170342031866,-1.84448981285095,0.485590904951096,1,,,,,,,,,,,,,,,,
,3823627131.41156,5.00318312644959,45000.21484375,,,6,,,,31.4133701324463,,,100,,,,,,,,,,,,,,,,,,,,,,4.99688100814819,5.00331020355225,45000.21484375,45000.21484375,,,3.83061099052429,,1,0,0,0,0.013885498046875,30.7917900085449,1,1,1,5.00337028503418,0,4232058144,5.00043377876282,,,0.0428282854299854,0.0022465558955885,0.0450729655118497,0.00224863297264945,0.690270245075226,0.976942181587219,30.2145862579346,0,35,4,200,-0.0141970328986645,-1.84835767745972,0.473764419555664,1,,,,,,,,,,,,,,,,
,3823627223.46878,5.0031087398529,30000.46484375,,,6,,,,31.4133701324463,,,100,,,,,,,,,,,,,,,,,,,,,,4.99697780609131,5.00302314758301,30000.46484375,30000.46484375,,,3.82691311836243,,1,0,0,0,0.013885498046875,31.7693061828613,1,1,1,5.00331735610962,0,4232058080,5.00037522315979,,,0.0431323189960095,0.00225781616847258,0.0453013681170415,0.00225971245905814,0.696397244930267,0.984095215797424,30.2372283935547,0.200690224766731,35,4,200,-0.00271900114603341,-1.84409165382385,0.460894763469696,1,,,,,,,,,,,,,,,,
,3823627313.7885,5.00274968147278,15000.2392578125,,,6,,,,31.4133701324463,,,100,,,,,,,,,,,,,,,,,,,,,,4.99728488922119,5.00301122665405,15000.2392578125,15000.2392578125,,,3.82342457771301,,1,0,0,0,0.013885498046875,30.7917900085449,1,1,1,5.00316953659058,0,4232058112,5.0004093170166,,,0.0429079900751916,0.00224684637206139,0.0450844645602708,0.00224878332754684,0.695370674133301,0.987535536289215,30.2315769195557,0.20077295601368,35,4,200,-0.00250865379348397,-1.82885885238647,0.454055994749069,1,,,,,,,,,,,,,,,,
,3823627402.42254,5.00306534767151,9000.48828125,,,6,,,,31.4133701324463,,,100,,,,,,,,,,,,,,,,,,,,,,4.99733734130859,5.00301170349121,9000.48828125,9000.48828125,,,3.8233814239502,,1,0,0,0,0.013885498046875,31.2805480957031,1,1,1,5.00317716598511,0,4232058272,5.00036263465881,,,0.0426884977187221,0.0022351635562065,0.0448528658377029,0.0022371971285135,0.695622801780701,0.988824784755707,30.2322044372559,0.25369268655777,35,4,200,-0.00308128213509917,-1.82224762439728,0.447091698646545,1,,,,,,,,,,,,,,,,
,3823627470.3435,5.00291705131531,7500.3642578125,,,6,,,,31.4133701324463,,,100,,,,,,,,,,,,,,,,,,,,,,4.99721670150757,5.00276803970337,7500.3642578125,7500.3642578125,,,3.82246160507202,,1,0,0,0,0.013885498046875,31.2805480957031,1,1,1,5.00327587127686,0,4232058400,5.00043258666992,,,0.0425867149809162,0.00222957504387832,0.0447390870147651,0.00223151534803774,0.695970058441162,0.989110767841339,30.2334308624268,,35,4,200,-0.00255793682299554,-1.81391501426697,0.440770506858826,1,,,,,,,,,,,,,,,,
,3823627539.70519,5.00301122665405,6000.3134765625,,,6,,,,31.4133701324463,,,100,,,,,,,,,,,,,,,,,,,,,,4.99730682373047,5.00298500061035,6000.3134765625,6000.3134765625,,,3.8253116607666,,1,0,0,0,0.013885498046875,31.7693061828613,1,1,1,5.00319385528564,0,4232058528,5.00036907196045,,,0.0424236840967942,0.00222063517244365,0.0445588347932883,0.00222251912311892,0.696514964103699,0.989358365535736,30.2354602813721,0.246861547231674,35,4,200,-0.0022531128488481,-1.81183803081512,0.435105234384537,1,,,,,,,,,,,,,,,,
,3823627609.58744,5.00291299819946,4500.201171875,,,6,,,,31.4133701324463,,,100,,,,,,,,,,,,,,,,,,,,,,4.99727201461792,5.00286912918091,4500.201171875,4500.201171875,,,3.82478213310242,,1,0,0,0,0.013885498046875,31.2805480957031,1,1,1,5.00311851501465,0,4232058528,5.00037484169006,,,0.0421053724960867,0.00220330641192472,0.0442107097995776,0.00220514736786734,0.697421014308929,0.989664018154144,30.2389984130859,0,35,4,200,-0.00200190325267613,-1.79970300197601,0.43128514289856,1,,,,,,,,,,,,,,,,
,3823627679.47549,5.00290775299072,3000.32177734375,,,6,,,,31.4133701324463,,,100,,,,,,,,,,,,,,,,,,,,,,4.99737453460693,5.00301933288574,3000.32177734375,3000.32177734375,,,3.8247504234314,,1,0,0,0,0.013885498046875,31.7693061828613,1,1,1,5.00320816040039,0,4232058336,5.00033874511719,,,0.0412279488138795,0.00215612592159084,0.0432657853181818,0.00215801039849141,0.699190437793732,0.98994642496109,30.2460784912109,0,35,4,200,-0.00172744120936841,-1.75414633750916,0.421204119920731,1,,,,,,,,,,,,,,,,
,3823627746.74504,5.00283551216126,1500.27075195313,,,6,,,,31.4133701324463,,,100,,,,,,,,,,,,,,,,,,,,,,4.99733829498291,5.00285911560059,1500.27075195313,1500.27075195313,,,3.8226432800293,,1,0,0,0,0.013885498046875,31.7693061828613,1,1,1,5.00308513641357,0,4232058336,5.00045018196106,,,0.0368975114761415,0.00192731427697633,0.0386728509129878,0.00192891872337828,0.702885746955872,0.990215122699738,30.2607078552246,5.50097322463989,35,4,200,-0.00137226982042193,-1.57045829296112,0.374191015958786,1,,,,,,,,,,,,,,,,
,3823627827.97939,5.00283145904541,600.484741210937,,,6,,,,31.4133701324463,,,100,,,,,,,,,,,,,,,,,,,,,,4.99743604660034,5.00287246704102,600.484741210937,600.484741210937,,,3.82072234153748,,1,0,0,0,0.013885498046875,31.7693061828613,1,1,1,5.00307035446167,0,4232058368,5.00047125816345,,,0.026138671642381,0.001364165311051,0.0273721116805268,0.00136525877300294,0.705528438091278,0.990484356880188,30.2712287902832,,35,4,200,-0.00105242803692818,-1.11436474323273,0.26537612080574,1,,,,,,,,,,,,,,,,
,3823627894.92971,5.00299143791199,0.0977749302983284,,,6,,,,31.4133701324463,,,100,,,,,,,,,,,,,,,,,,,,,,4.99728202819824,5.00301647186279,0.0977749302983284,0.0977749302983284,,,3.82242846488953,,1,0,0,0,0.013885498046875,31.7693061828613,1,1,1,5.00322198867798,0,4232058432,5.00041251182556,,,0.00465128490735172,0.000240422128861511,0.0048231221422481,0.000240579499776351,0.737408578395843,0.985870957374573,30.4005508422852,5.04649114608765,35,4,200,-0.00094999693101272,-0.193950355052948,0.046799149364233,1,,,,,,,,,,,,,,,,
,3823627960.90501,5.00288009643555,-599.824768066406,,,6,,,,31.4133701324463,,,100,,,,,,,,,,,,,,,,,,,,,,4.99744319915771,5.00293159484863,-599.824768066406,-599.824768066406,,,3.82341933250427,,1,0,0,0,0.013885498046875,31.7693061828613,1,1,1,5.00318098068237,0,4232058400,5.00040097236633,,,-0.0211385521596328,0.00110667035977451,-0.022206916878553,0.00110763197694763,0.696003913879395,0.990356743335724,30.2327690124512,3.74131369590759,35,4,200,-0.000640079495497048,-0.226480275392532,0.891780912876129,1,,,,,,,,,,,,,,,,
,3823628040.46662,5.00271129608154,-1499.92858886719,,,6,,,,31.4133701324463,,,100,,,,,,,,,,,,,,,,,,,,,,4.9974250793457,5.00295209884644,-1499.92858886719,-1499.92858886719,,,3.8211362361908,,1,0,0,0,0.013885498046875,31.2805480957031,1,1,1,5.0031476020813,0,4232058336,5.0002968788147,,,-0.0362104372560007,0.00189216400130902,-0.0379674969494647,0.00189373876356932,0.701691508293152,0.990157723426819,30.2559356689453,,35,4,200,-0.000225098294322379,-0.382145196199417,1.53650403022766,1,,,,,,,,,,,,,,,,
,3823628115.8292,5.00304627418518,-3000.22387695313,,,6,,,,31.4133701324463,,,100,,,,,,,,,,,,,,,,,,,,,,4.99744367599487,5.00291776657105,-3000.22387695313,-3000.22387695313,,,3.81960940361023,,1,0,0,0,0.013885498046875,31.2805480957031,1,1,1,5.00332355499268,0,4232058368,5.00032458305359,,,-0.041213838802697,0.0021554895401438,-0.04325310898122,0.00215737920667151,0.699048280715942,0.989903867244721,30.2454833984375,0,35,4,200,-0.000776439963374287,-0.43133682012558,1.74485850334167,1,,,,,,,,,,,,,,,,
,3823628191.04791,5.00299215316772,-4500.3603515625,,,6,,,,31.4133701324463,,,100,,,,,,,,,,,,,,,,,,,,,,4.9974684715271,5.00303840637207,-4500.3603515625,-4500.3603515625,,,3.81976103782654,,1,0,0,0,0.013885498046875,31.7693061828613,1,1,1,5.00321340560913,0,4232058240,5.00049366950989,,,-0.0420956125688109,0.00220281447477281,-0.0442023542428625,0.00220473137152325,0.697395086288452,0.989620208740234,30.2390232086182,,35,4,200,-0.00112227245699614,-0.443962812423706,1.78064167499542,1,,,,,,,,,,,,,,,,
,3823628265.98085,5.0028510093689,-6000.5087890625,,,6,,,,31.4133701324463,,,100,,,,,,,,,,,,,,,,,,,,,,4.99735498428345,5.00312805175781,-6000.5087890625,-6000.5087890625,,,3.81814479827881,,1,0,0,0,0.013885498046875,31.2805480957031,1,1,1,5.00324296951294,0,4232058464,5.00037569999695,,,-0.0424147262786119,0.00222012917223801,-0.0445499861899236,0.00222207785643104,0.696564197540283,0.989329159259796,30.2358493804932,0,35,4,200,-0.00130491086747497,-0.454149335622787,1.79945969581604,1,,,,,,,,,,,,,,,,
,3823628342.00414,5.00280261039734,-7500.22998046875,,,6,,,,31.4133701324463,,,100,,,,,,,,,,,,,,,,,,,,,,4.99743986129761,5.00293111801147,-7500.22998046875,-7500.22998046875,,,3.81889820098877,,1,0,0,0,0.013885498046875,31.2805480957031,1,1,1,5.00308609008789,0,4232058368,5.000297498703,,,-0.0425804124734174,0.0022291025305954,-0.0447298291735538,0.00223105467683447,0.696160733699799,0.989056348800659,30.2341823577881,0,35,4,200,-0.0019400684395805,-0.453516155481338,1.80174779891968,1,,,,,,,,,,,,,,,,
,3823628418.19684,5.00289416313171,-9000.5244140625,,,6,,,,31.4133701324463,,,100,,,,,,,,,,,,,,,,,,,,,,4.9973464012146,5.00290632247925,-9000.5244140625,-9000.5244140625,,,3.81690549850464,,1,0,0,0,0.013885498046875,31.2805480957031,1,1,1,5.00309658050537,0,4232058368,5.00033707618713,,,-0.0426846731142562,0.00223476406147542,-0.0448429746024882,0.00223670586246788,0.695889711380005,0.988772094249725,30.2332916259766,0.000173115622601472,35,4,200,-0.00218309299089015,-0.461849987506866,1.81143939495087,1,,,,,,,,,,,,,,,,
,3823628507.08026,5.00285673141479,-15000.337890625,,,6,,,,31.4133701324463,,,100,,,,,,,,,,,,,,,,,,,,,,4.99723672866821,5.00296449661255,-15000.337890625,-15000.337890625,,,3.81265091896057,,1,0,0,0,0.013885498046875,31.7693061828613,1,1,1,5.00313854217529,0,4232058208,5.00034804344177,,,-0.0429015666898958,0.00224631019529401,-0.0450748320752505,0.00224829982713786,0.695635497570038,0.987639427185059,30.2327613830566,3.74129295349121,35,4,200,-0.00195774622261524,-0.461930990219116,1.82181262969971,1,,,,,,,,,,,,,,,,
,3823628594.89929,5.00308632850647,-30000.369140625,,,6,,,,31.4133701324463,,,100,,,,,,,,,,,,,,,,,,,,,,4.99698209762573,5.00325298309326,-30000.369140625,-30000.369140625,,,3.81269645690918,,1,0,0,0,0.013885498046875,31.2805480957031,1,1,1,5.00336313247681,0,4232058624,5.00042915344238,,,-0.0431299587511912,0.00225727451931832,-0.0452931087715358,0.00225929470826166,0.696952164173126,0.984266996383667,30.2395668029785,0,35,4,200,-0.00233064335770905,-0.480409622192383,1.82994520664215,1,,,,,,,,,,,,,,,,
,3823628682.61934,5.00315070152283,-45000.49609375,,,6,,,,31.4133701324463,,,100,,,,,,,,,,,,,,,,,,,,,,4.99692487716675,5.00331211090088,-45000.49609375,-45000.49609375,,,3.8146595954895,,1,0,0,0,0.013885498046875,31.2805480957031,1,1,1,5.00343227386475,0,4232058336,5.00054521560669,,,-0.043235066400958,0.00226118662115112,-0.0453671087818871,0.00226313592526006,0.699065566062927,0.980498731136322,30.2497692108154,0,35,4,200,-0.00188350642565638,-0.491801172494888,1.83308506011963,1,,,,,,,,,,,,,,,,
,3823628771.15903,5.00333261489868,-60000.34375,,,6,,,,31.4133701324463,,,100,,,,,,,,,,,,,,,,,,,,,,4.99676942825317,5.00349092483521,-60000.34375,-60000.34375,,,3.81622695922852,,1,0,0,0,0.013885498046875,31.7693061828613,1,1,1,5.00359201431274,0,4232058432,5.0003821849823,,,-0.0432917616649233,0.00226207448349428,-0.0453794357589026,0.00226393645563242,0.701854884624481,0.976670861244202,30.2629089355469,5.50117349624634,35,4,200,-0.00214811554178596,-0.509353697299957,1.83181977272034,1,,,,,,,,,,,,,,,,
,3823629488.16761,299.988739013672,-70000.0703125,,,6,,,,31.4133701324463,,,100,,,,,,,,,,,,,,,,,,,,,,299.985534667969,299.991058349609,-70000.0703125,-70000.0703125,,,7.19459295272827,,1,0,0,0,0.013885498046875,31.2805480957031,1,1,1,299.991119384766,0,4232058464,299.987643432617,,,-0.040206554266713,0.00200608151389616,-0.040206600969748,0.00200608180353046,0.972459495067596,0.972496390342712,31.4079456329346,2.043062067969E-6,35,4,200,-0.000589254661463201,-0.418493211269379,1.56906950473785,1,,,,,,,,,,,,,,,,
,3823629577.88983,299.990447998047,-55000.36328125,,,6,,,,31.4133701324463,,,100,,,,,,,,,,,,,,,,,,,,,,299.989074707031,299.991088867188,-55000.36328125,-55000.36328125,,,7.1524600982666,,1,0,0,0,0.013885498046875,31.7693061828613,1,1,1,299.989807128906,0,4232058176,299.990048217773,,,-0.0401650056879632,0.0020038306978344,-0.0401653351894513,0.00200383199999437,0.975894272327423,0.97620952129364,31.3985729217529,0,35,4,200,0.00254438491538167,-0.396994054317474,1.57965004444122,1,,,,,,,,,,,,,,,,
,3823629668.42101,299.99235534668,-40000.484375,,,6,,,,31.4133701324463,,,100,,,,,,,,,,,,,,,,,,,,,,299.989959716797,299.995025634766,-40000.484375,-40000.484375,,,7.12746477127075,,1,0,0,0,0.0139617919921875,30.7917900085449,1,1,1,299.990325927734,0,4232058240,299.993356323242,,,-0.0400795196236595,0.00199940754523109,-0.0400800068670851,0.00199940838574577,0.979432642459869,0.980011165142059,31.3949108123779,0,35,4,200,0.00287077715620399,-0.389362424612045,1.58013188838959,1,,,,,,,,,,,,,,,,
,3823629758.46096,299.999969482422,-25000.35546875,,,6,,,,31.4133701324463,,,100,,,,,,,,,,,,,,,,,,,,,,299.996307373047,300.005493164063,-25000.35546875,-25000.35546875,,,7.11378288269043,,1,0,0,0,0.013885498046875,30.7917900085449,1,1,1,299.996887207031,0,4232058112,300.001583862305,,,-0.0399070665133261,0.00199067712121263,-0.0399075991694853,0.00199067798702128,0.982840716838837,0.983610272407532,31.3939933776855,1.38848702135874E-6,35,4,200,0.00286300363950431,-0.380810260772705,1.56798100471497,1,,,,,,,,,,,,,,,,
,3823629849.57146,300.006240844727,-10000.3349609375,,,6,,,,31.4133701324463,,,100,,,,,,,,,,,,,,,,,,,,,,300.003631591797,300.012725830078,-10000.3349609375,-10000.3349609375,,,7.11483907699585,,1,0,0,0,0.013885498046875,31.7693061828613,1,1,1,300.004211425781,0,4232057984,300.008898925781,,,-0.0394390691803478,0.00196723435322555,-0.0394395648709233,0.00196723627111697,0.986009061336517,0.986863672733307,31.3949947357178,0,35,4,200,0.00257427734322846,-0.365899950265884,1.548672914505,1,,,,,,,,,,,,,,,,
,3823629932.35373,300.006103515625,-8500.4306640625,,,6,,,,31.4133701324463,,,100,,,,,,,,,,,,,,,,,,,,,,300.002502441406,300.0126953125,-8500.4306640625,-8500.4306640625,,,7.13595724105835,,1,0,0,0,0.013885498046875,31.7693061828613,1,1,1,300.003021240234,0,4232058464,300.008358764648,,,-0.0393339611575266,0.00196197523255321,-0.039334253525069,0.00196197552850242,0.986642360687256,0.987199008464813,31.3988056182861,0,35,4,200,0.00315840076655149,-0.363305658102036,1.55521047115326,1,,,,,,,,,,,,,,,,
,3823630002.94583,300.004852294922,-7000.29443359375,,,6,,,,31.4133701324463,,,100,,,,,,,,,,,,,,,,,,,,,,300.001739501953,300.010955810547,-7000.29443359375,-7000.29443359375,,,7.18331050872803,,1,0,0,0,0.013885498046875,32.2580642700195,1,1,1,300.001953125,0,4232058432,300.007055664062,,,-0.0391838150094719,0.00195447233604118,-0.0391839913291263,0.00195447229792199,0.987137258052826,0.987493455410004,31.4018955230713,5.6037392616272,35,4,200,0.00260710460133851,-0.352921217679977,1.54898309707642,1,,,,,,,,,,,,,,,,
,3823630073.00495,300.002792358398,-5500.451171875,,,6,,,,31.4133701324463,,,100,,,,,,,,,,,,,,,,,,,,,,299.999481201172,300.008483886719,-5500.451171875,-5500.451171875,,,7.25750160217285,,1,0,0,0,0.013885498046875,31.7693061828613,1,1,1,299.999786376953,0,4232058592,300.005087280273,,,-0.038956966906785,0.0019431458334394,-0.0389570420174693,0.00194314577514122,0.987616002559662,0.987775087356567,31.4058170318604,5.3437152018887E-6,35,4,200,0.00234943022951484,-0.35643857717514,1.53516888618469,1,,,,,,,,,,,,,,,,
,3823630142.38197,300.000228881836,-4000.21704101562,,,6,,,,31.4133701324463,,,100,,,,,,,,,,,,,,,,,,,,,,299.997131347656,300.006591796875,-4000.21704101562,-4000.21704101562,,,7.38049077987671,,1,0,0,0,0.013885498046875,31.7693061828613,1,1,1,299.997375488281,0,4232058624,300.002392578125,,,-0.0385502822624633,0.00192284674646185,-0.0385502896049529,0.00192284684879402,0.988227725028992,0.988239407539368,31.4113693237305,0,35,4,200,0.00184674409683794,-0.35309174656868,1.52082276344299,1,,,,,,,,,,,,,,,,
,3823630212.35629,299.99967956543,-2500.3740234375,,,6,,,,31.4133701324463,,,100,,,,,,,,,,,,,,,,,,,,,,299.996765136719,300.005889892578,-2500.3740234375,-2500.3740234375,,,7.55893564224243,,1,0,0,0,0.013885498046875,32.2580642700195,1,1,1,299.997009277344,0,4232058304,300.002416992187,,,-0.037487532351941,0.00186983808865358,-0.0374875959236192,0.00186983793117309,0.988202810287476,0.988354623317719,31.4205722808838,0.18643556535244,35,4,200,0.00155768811237067,-0.337571650743484,1.47458040714264,1,,,,,,,,,,,,,,,,
,3823630279.90513,300.002532958984,-1000.15203857422,,,6,,,,31.4133701324463,,,100,,,,,,,,,,,,,,,,,,,,,,300.000305175781,300.008605957031,-1000.15203857422,-1000.15203857422,,,7.78234624862671,,1,0,0,0,0.013885498046875,31.7693061828613,1,1,1,300.00048828125,0,4232058368,300.00491027832,,,-0.0315132936786887,0.0015718865037601,-0.0315141711569429,0.00157188683256366,0.986375391483307,0.988582074642181,31.4417572021484,0,35,4,200,0.00105200952384621,-0.287730753421783,1.23797118663788,1,,,,,,,,,,,,,,,,
,3823630362.63898,300.001480102539,-400.449462890625,,,6,,,,31.4133701324463,,,100,,,,,,,,,,,,,,,,,,,,,,299.999114990234,300.006500244141,-400.449462890625,-400.449462890625,,,8.09738540649414,,1,0,0,0,0.013885498046875,31.2805480957031,1,1,1,299.999359130859,0,4232058592,300.003536987305,,,-0.0200891595741481,0.00100207045759585,-0.0200901233756669,0.00100207141497045,0.98488050699234,0.9883993268013,31.4503936767578,5.08834364154609E-6,35,4,200,0.00134852132759988,-0.179346472024918,0.795284032821655,1,,,,,,,,,,,,,,,,
,3823630430.59835,299.999755859375,200.133071899414,,,6,,,,31.4133701324463,,,100,,,,,,,,,,,,,,,,,,,,,,299.997680664063,300.005035400391,200.133071899414,200.133071899414,,,8.29551315307617,,1,0,0,0,0.013885498046875,31.7693061828613,1,1,1,299.997894287109,0,4232058528,300.002114868164,,,0.0151243497330016,0.000754415108354722,0.0151250209136066,0.000754415009815715,0.985345780849457,0.988786339759827,31.4493942260742,0,35,4,200,0.00134837569203228,-0.597671568393707,0.139775231480598,1,,,,,,,,,,,,,,,,
,3823630497.85106,299.996963500977,800.1044921875,,,6,,,,31.4133701324463,,,100,,,,,,,,,,,,,,,,,,,,,,299.993896484375,300.003967285156,800.1044921875,800.1044921875,,,8.16683959960937,,1,0,0,0,0.013885498046875,31.7693061828613,1,1,1,299.994293212891,0,4232058400,299.999749755859,,,0.0299750081909718,0.00149518337492174,0.0299763782180232,0.00149518437006916,0.985092341899872,0.988503217697144,31.4496116638184,0,35,4,200,0.000434582616435364,-1.18423712253571,0.266656100749969,1,,,,,,,,,,,,,,,,
,3823630576.67956,299.996383666992,2000.16955566406,,,6,,,,31.4133701324463,,,100,,,,,,,,,,,,,,,,,,,,,,299.992950439453,300.004669189453,2000.16955566406,2000.16955566406,,,8.06819438934326,,1,0,0,0,0.013885498046875,32.7468223571777,1,1,1,299.993225097656,0,4232058400,299.999801635742,,,0.0367798511232122,0.00183455741104938,0.03678027966485,0.00183455698320642,0.987417340278626,0.988400161266327,31.4319820404053,0,35,4,200,0.000703052384778857,-1.44378650188446,0.334340572357178,1,,,,,,,,,,,,,,,,
,3823630652.47512,299.997711181641,3500.36694335937,,,6,,,,31.4133701324463,,,100,,,,,,,,,,,,,,,,,,,,,,299.995361328125,300.005798339844,3500.36694335937,3500.36694335937,,,8.00699520111084,,1,0,0,0,0.013885498046875,31.7693061828613,1,1,1,299.995544433594,0,4232058400,300.001468234592,,,0.038342359237527,0.00191248411322831,0.0383424984538689,0.00191248382053162,0.987822115421295,0.988136887550354,31.4238719940186,0,35,4,200,0.000739519018679857,-1.50838661193848,0.345449924468994,1,,,,,,,,,,,,,,,,
,3823630727.01337,299.997589111328,5000.43017578125,,,6,,,,31.4133701324463,,,100,,,,,,,,,,,,,,,,,,,,,,299.993835449219,300.006103515625,5000.43017578125,5000.43017578125,,,7.95011854171753,,1,0,0,0,0.013885498046875,31.7693061828613,1,1,1,299.994445800781,0,4232058336,300.000939941406,,,0.0388642549973627,0.0019385201719833,0.0388643260622723,0.00193851959236485,0.987691402435303,0.987865447998047,31.4212436676025,,35,4,200,0.00124316767323762,-1.52755773067474,0.354774385690689,1,,,,,,,,,,,,,,,,
,3823630803.00463,299.997863769531,6500.24853515625,,,6,,,,31.4133701324463,,,100,,,,,,,,,,,,,,,,,,,,,,299.993927001953,300.005981445313,6500.24853515625,6500.24853515625,,,7.90503168106079,,1,0,0,0,0.013885498046875,31.7693061828613,1,1,1,299.994781494141,0,4232058336,300.000988769531,,,0.0391309777147657,0.00195182952722752,0.0391310468601635,0.00195182955775858,0.987443625926971,0.987583875656128,31.4205131530762,0,35,4,200,0.00174022477585822,-1.53448784351349,0.363507091999054,1,,,,,,,,,,,,,,,,
,3823630877.96473,299.997329711914,8000.36083984375,,,6,,,,31.4133701324463,,,100,,,,,,,,,,,,,,,,,,,,,,299.993927001953,300.005523681641,8000.36083984375,8000.36083984375,,,7.86186599731445,,1,0,0,0,0.013885498046875,31.7693061828613,1,1,1,299.994354248047,0,4232058464,300.000402832031,,,0.03929934925739,0.00196023550584227,0.039299408021002,0.00196023490383006,0.987152993679047,0.98729407787323,31.4206161499023,,35,4,200,0.00192004872951657,-1.54570841789246,0.361582040786743,1,,,,,,,,,,,,,,,,
,3823630953.89295,299.998016357422,9500.2158203125,,,6,,,,31.4133701324463,,,100,,,,,,,,,,,,,,,,,,,,,,299.994506835937,300.006256103516,9500.2158203125,9500.2158203125,,,7.83318376541138,,1,0,0,0,0.013885498046875,31.7693061828613,1,1,1,299.994781494141,0,4232058368,300.001278686523,,,0.0394198556159422,0.00196625358501434,0.0394199360295356,0.00196625358822035,0.986846923828125,0.987002789974213,31.4210758209229,1,35,4,200,0.00200099847279489,-1.5486091375351,0.365247339010239,1,,,,,,,,,,,,,,,,
,3823631046.41474,299.997573852539,20000.265625,,,6,,,,31.4133701324463,,,100,,,,,,,,,,,,,,,,,,,,,,299.993682861328,300.008148193359,20000.265625,20000.265625,,,7.7952823638916,,1,0,0,0,0.013885498046875,31.7693061828613,1,1,1,299.993743896484,0,4232058112,300.002157592773,,,0.0398247087497098,0.00198651304762545,0.0398248712524626,0.00198651230029504,0.984580278396606,0.984871983528137,31.4247570037842,0,35,4,200,0.002118717180565,-1.55587518215179,0.379352420568466,1,,,,,,,,,,,,,,,,
,3823631134.89103,299.997543334961,35000.25,,,6,,,,31.4133701324463,,,100,,,,,,,,,,,,,,,,,,,,,,299.993377685547,300.006378173828,35000.25,35000.25,,,7.76667165756226,,1,0,0,0,0.0139617919921875,31.7693061828613,1,1,1,299.994140625,0,4232058144,300.000689697266,,,0.0400572398148861,0.00199824849605304,0.040057859913908,0.00199824749371596,0.980621576309204,0.981464385986328,31.4349155426025,0.19297282397747,35,4,200,0.00193205266259611,-1.56933164596558,0.389327168464661,1,,,,,,,,,,,,,,,,
,3823631222.74714,299.996704101562,50000.37890625,,,6,,,,31.4133701324463,,,100,,,,,,,,,,,,,,,,,,,,,,299.991943359375,300.005493164063,50000.37890625,50000.37890625,,,7.74018430709839,,1,0,0,0,0.013885498046875,31.7693061828613,1,1,1,299.992523193359,0,4232058368,299.999798583984,,,0.040176771861598,0.00200439957862569,0.0401784058358023,0.00200440167737195,0.976265847682953,0.977997541427612,31.4472694396973,0,35,4,200,0.00181438424624503,-1.56918942928314,0.407963991165161,1,,,,,,,,,,,,,,,,
,3823631311.11101,299.995498657227,65000.15234375,,,6,,,,31.4133701324463,,,100,,,,,,,,,,,,,,,,,,,,,,299.990905761719,300.004272460937,65000.15234375,65000.15234375,,,7.70711374282837,,1,0,0,0,0.013885498046875,32.2580642700195,1,1,1,299.991516113281,0,4232058336,299.998492431641,,,0.0402399363089142,0.0020078242213012,0.0402434864979285,0.00200782610553361,0.971099317073822,0.97429370880127,31.46364402771,5.60924625396729,35,4,200,0.00244718650355935,-1.56551289558411,0.421307176351547,1,,,,,,,,,,,,,,,,
,3823631399.5851,299.996597290039,60000.46875,,,6,,,,31.4133701324463,,,100,,,,,,,,,,,,,,,,,,,,,,299.992095947266,300.007019042969,60000.46875,60000.46875,,,7.6919846534729,,1,0,0,0,0.013885498046875,31.2805480957031,1,1,1,299.992095947266,0,4232058144,300.000476074219,,,0.0402321796271862,0.00200735190519879,0.0402350447138359,0.00200735522978091,0.972615003585815,0.975283145904541,31.4582614898682,2.48657852353062E-5,35,4,200,-0.00161945156287402,-1.57905328273773,0.405626773834229,1,,,,,,,,,,,,,,,,
,3823631492.45173,299.997116088867,45000.27734375,,,6,,,,31.4133701324463,,,100,,,,,,,,,,,,,,,,,,,,,,299.992156982422,300.006927490234,45000.27734375,45000.27734375,,,7.66920900344849,,1,0,0,0,0.013885498046875,31.7693061828613,1,1,1,299.992736816406,0,4232058240,300.000839233398,,,0.0401545565437218,0.00200323154307405,0.0401558048263071,0.00200323142095313,0.97755640745163,0.97898930311203,31.4434299468994,0.000132620363729075,35,4,200,-0.00265503721311688,-1.58201837539673,0.392499983310699,1,,,,,,,,,,,,,,,,
,3823631583.43412,299.996948242188,30000.46484375,,,6,,,,31.4133701324463,,,100,,,,,,,,,,,,,,,,,,,,,,299.991943359375,300.006683349609,30000.46484375,30000.46484375,,,7.65034055709839,,1,0,0,0,0.013885498046875,31.7693061828613,1,1,1,299.992614746094,0,4232058208,300.000524902344,,,0.0400091967556897,0.0019958064429369,0.0400097146213461,0.00199580642389354,0.981836795806885,0.982564270496368,31.4327735900879,0,35,4,200,-0.00277683907188475,-1.57157850265503,0.37172532081604,1,,,,,,,,,,,,,,,,
,3823631672.83623,299.996871948242,15000.3740234375,,,6,,,,31.4133701324463,,,100,,,,,,,,,,,,,,,,,,,,,,299.992218017578,300.006164550781,15000.3740234375,15000.3740234375,,,7.62866163253784,,1,0,0,0,0.013885498046875,31.7693061828613,1,1,1,299.992828369141,0,4232058080,300.000259399414,,,0.0396924952056264,0.00197988848367238,0.0396926976408286,0.00197988800072023,0.985549390316009,0.985923945903778,31.4258441925049,0,35,4,200,-0.00258771679364145,-1.56093895435333,0.365991920232773,1,,,,,,,,,,,,,,,,
,3823631762.01246,299.995849609375,9000.4267578125,,,6,,,,31.4133701324463,,,100,,,,,,,,,,,,,,,,,,,,,,299.991577148438,300.005065917969,9000.4267578125,9000.4267578125,,,7.61499738693237,,1,0,0,0,0.013885498046875,31.7693061828613,1,1,1,299.991729736328,0,4232058656,299.999206542969,,,0.0393914498211622,0.00196483819607094,0.0393916481540299,0.0019648379777685,0.986802101135254,0.987197875976563,31.4256134033203,5.23136568069458,35,4,200,-0.00324075948446989,-1.5588858127594,0.350981682538986,1,,,,,,,,,,,,,,,,
,3823631831.07701,299.995330810547,7500.42529296875,,,6,,,,31.4133701324463,,,100,,,,,,,,,,,,,,,,,,,,,,299.991485595703,300.00439453125,7500.42529296875,7500.42529296875,,,7.59802389144897,,1,0,0,0,0.013885498046875,31.7693061828613,1,1,1,299.991851806641,0,4232058560,299.998577880859,,,0.0392570220845268,0.00195812677032882,0.0392572620472244,0.00195812713166191,0.987014055252075,0.987478792667389,31.4265117645264,0,35,4,200,-0.00263763405382633,-1.54885840415955,0.356348067522049,1,,,,,,,,,,,,,,,,
,3823631901.45639,299.996246337891,6000.42333984375,,,6,,,,31.4133701324463,,,100,,,,,,,,,,,,,,,,,,,,,,299.991943359375,300.006072998047,6000.42333984375,6000.42333984375,,,7.58799314498901,,1,0,0,0,0.013885498046875,31.7693061828613,1,1,1,299.992736816406,0,4232058400,299.999954223633,,,0.0390647572669198,0.00194853251596789,0.0390650413330184,0.00194853236086253,0.987237930297852,0.987827479839325,31.4280052185059,0,35,4,200,-0.00232996558770537,-1.54147529602051,0.349359065294266,1,,,,,,,,,,,,,,,,
,3823631970.64568,299.994812011719,4500.34814453125,,,6,,,,31.4133701324463,,,100,,,,,,,,,,,,,,,,,,,,,,299.989715576172,300.005767822266,4500.34814453125,4500.34814453125,,,7.57261800765991,,1,0,0,0,0.013885498046875,32.2580642700195,1,1,1,299.990844726562,0,4232058400,299.999465942383,,,0.0387318983787356,0.00193192990692089,0.0387322991233533,0.00193192993192,0.987212657928467,0.988047957420349,31.4307250976562,0.0695727467536926,35,4,200,-0.00206257798708975,-1.52893459796906,0.344424277544022,1,,,,,,,,,,,,,,,,
,3823632042.5121,299.994201660156,3000.41943359375,,,6,,,,31.4133701324463,,,100,,,,,,,,,,,,,,,,,,,,,,299.990539550781,300.003845214844,3000.41943359375,3000.41943359375,,,7.55820989608765,,1,0,0,0,0.013885498046875,31.7693061828613,1,1,1,299.991577148438,0,4232058304,299.997906494141,,,0.0380011141434529,0.00189548717551442,0.0380017942088463,0.00189548615470266,0.986842691898346,0.988327324390411,31.4365482330322,8.72336931934115E-6,35,4,200,-0.00170829286798835,-1.4939227104187,0.343415081501007,1,,,,,,,,,,,,,,,,
,3823632110.52386,299.996337890625,1500.31970214844,,,6,,,,31.4133701324463,,,100,,,,,,,,,,,,,,,,,,,,,,299.992736816406,300.005706787109,1500.31970214844,1500.31970214844,,,7.54806900024414,,1,0,0,0,0.013885498046875,31.7693061828613,1,1,1,299.993621826172,0,4232058592,299.999887084961,,,0.0350513617064364,0.00174839975280037,0.0350531064738976,0.00174840117663414,0.984996497631073,0.98872172832489,31.4511528015137,1.05741582956398E-5,35,4,200,-0.00142677337862551,-1.38250887393951,0.312108665704727,1,,,,,,,,,,,,,,,,
,3823632191.57339,299.991134643555,600.240356445313,,,6,,,,31.4133701324463,,,100,,,,,,,,,,,,,,,,,,,,,,299.987518310547,300.000610351562,600.240356445313,600.240356445313,,,7.53333330154419,,1,0,0,0,0.013885498046875,31.7693061828613,1,1,1,299.988708496094,0,4232058592,299.994775390625,,,0.0254192615239682,0.00126800051856629,0.0254217025438727,0.00126800233555323,0.982113540172577,0.98856395483017,31.4658794403076,0,35,4,200,-0.00111498916521668,-1.00485253334045,0.227772295475006,1,,,,,,,,,,,,,,,,
,3823632257.01646,299.988357543945,0.317768514156342,,,6,,,,31.4133701324463,,,100,,,,,,,,,,,,,,,,,,,,,,299.984069824219,299.998565673828,0.317768514156342,0.317768514156342,,,7.52527809143066,,1,0,0,0,0.013885498046875,31.2805480957031,1,1,1,299.984222412109,0,4232058368,299.99245300293,,,-0.00315396307498783,0.000157320108522649,-0.0031541072335258,0.00015732015034961,0.986308872699738,0.990172505378723,31.4498157501221,0.0542253330349922,35,4,200,-0.000944882398471236,-0.0367219746112823,0.121534928679466,1,,,,,,,,,,,,,,,,
,3823632322.8188,299.993682861328,-599.629272460937,,,6,,,,31.4133701324463,,,100,,,,,,,,,,,,,,,,,,,,,,299.990112304687,300.004180908203,-599.629272460937,-599.629272460937,,,7.51996755599976,,1,0,0,0,0.013885498046875,31.2805480957031,1,1,1,299.991363525391,0,4232058464,299.99755859375,,,-0.026809671296506,0.00133736073271464,-0.0268123434406667,0.00133736108440423,0.982031047344208,0.988859057426453,31.4672107696533,0,35,4,200,-0.000578561099246144,-0.245638325810432,1.05167281627655,1,,,,,,,,,,,,,,,,
,3823632402.26406,299.998947143555,-1500.01416015625,,,6,,,,31.4133701324463,,,100,,,,,,,,,,,,,,,,,,,,,,299.994903564453,300.011077880859,-1500.01416015625,-1500.01416015625,,,7.51559925079346,,1,0,0,0,0.013885498046875,31.7693061828613,1,1,1,299.995513916016,0,4232058336,300.003768920898,,,-0.0353314519449595,0.00176238117957657,-0.0353333135516062,0.00176238033016237,0.984619200229645,0.988587379455566,31.4527416229248,0,35,4,200,-0.000395108480006456,-0.321944832801819,1.3847119808197,1,,,,,,,,,,,,,,,,
,3823632477.30679,299.998046875,-3000.21166992188,,,6,,,,31.4133701324463,,,100,,,,,,,,,,,,,,,,,,,,,,299.993835449219,300.009490966797,-3000.21166992188,-3000.21166992188,,,7.52329444885254,,1,0,0,0,0.013885498046875,31.7693061828613,1,1,1,299.993835449219,0,4232058080,300.002792358398,,,-0.0380428540627437,0.00189757769936713,-0.0380437280764265,0.00189757844779728,0.986496388912201,0.988286972045898,31.439022064209,0,35,4,200,-0.000731835840269923,-0.34443536400795,1.49451398849487,1,,,,,,,,,,,,,,,,
,3823632552.2176,299.997283935547,-4500.3720703125,,,6,,,,31.4133701324463,,,100,,,,,,,,,,,,,,,,,,,,,,299.992828369141,300.007995605469,-4500.3720703125,-4500.3720703125,,,7.51875162124634,,1,0,0,0,0.013885498046875,32.2580642700195,1,1,1,299.993591308594,0,4232058432,300.001693725586,,,-0.0387470811487243,0.00193269524615416,-0.038747663008034,0.001932696122188,0.986857771873474,0.988016843795776,31.4339714050293,0,35,4,200,-0.00110799493268132,-0.360213756561279,1.51516902446747,1,,,,,,,,,,,,,,,,
,3823632626.89614,299.997177124023,-6000.32568359375,,,6,,,,31.4133701324463,,,100,,,,,,,,,,,,,,,,,,,,,,299.992553710937,300.007751464844,-6000.32568359375,-6000.32568359375,,,7.51249694824219,,1,0,0,0,0.013885498046875,32.2580642700195,1,1,1,299.993499755859,0,4232058432,300.001171875,,,-0.0390698235230446,0.00194879420822544,-0.0390702680648859,0.00194879377989874,0.986828744411469,0.987740695476532,31.4317531585693,5.60640287399292,35,4,200,-0.0013276698300615,-0.35804471373558,1.5345287322998,1,,,,,,,,,,,,,,,,
,3823632702.96694,299.995513916016,-7500.31494140625,,,6,,,,31.4133701324463,,,100,,,,,,,,,,,,,,,,,,,,,,299.991241455078,300.006652832031,-7500.31494140625,-7500.31494140625,,,7.50241661071777,,1,0,0,0,0.013885498046875,31.7693061828613,1,1,1,299.992065429687,0,4232058336,299.999905056424,,,-0.0392622952092449,0.00195839979458827,-0.0392627029271952,0.00195839988872955,0.986641466617584,0.987438857555389,31.4307231903076,4.49079198006075E-5,35,4,200,-0.00191312027163804,-0.36460068821907,1.54065036773682,1,,,,,,,,,,,,,,,,
,3823632778.86145,299.996078491211,-9000.537109375,,,6,,,,31.4133701324463,,,100,,,,,,,,,,,,,,,,,,,,,,299.992431640625,300.005432128906,-9000.537109375,-9000.537109375,,,7.49235773086548,,1,0,0,0,0.013885498046875,31.7693061828613,1,1,1,299.993682861328,0,4232058272,299.999865722656,,,-0.0393951211244163,0.00196503181502623,-0.0393955152917072,0.0019650319723639,0.986403107643127,0.987153708934784,31.4303741455078,,35,4,200,-0.00206659291870892,-0.372013807296753,1.54083037376404,1,,,,,,,,,,,,,,,,
,3823632866.88642,299.996597290039,-15000.3857421875,,,6,,,,31.4133701324463,,,100,,,,,,,,,,,,,,,,,,,,,,299.991455078125,300.007568359375,-15000.3857421875,-15000.3857421875,,,7.48839235305786,,1,0,0,0,0.013885498046875,31.7693061828613,1,1,1,299.991790771484,0,4232058240,300.000671386719,,,-0.0396926611844742,0.00197990691974253,-0.0396930957729353,0.00197990710422624,0.985199689865112,0.985952138900757,31.4311447143555,0,35,4,200,-0.00187545549124479,-0.376765489578247,1.5499439239502,1,,,,,,,,,,,,,,,,
,3823632954.49372,299.99397277832,-30000.34375,,,6,,,,31.4133701324463,,,100,,,,,,,,,,,,,,,,,,,,,,299.989105224609,300.004791259766,-30000.34375,-30000.34375,,,7.48488998413086,,1,0,0,0,0.013885498046875,31.2805480957031,1,1,1,299.989379882812,0,4232058080,299.998095703125,,,-0.0400099976339215,0.00199586511179236,-0.0400109454003069,0.001995864995356,0.981350183486938,0.982669711112976,31.439640045166,0,35,4,200,-0.00234318454749882,-0.394443571567535,1.56368470191956,1,,,,,,,,,,,,,,,,
,3823633042.62101,299.998046875,-45000.4609375,,,6,,,,31.4133701324463,,,100,,,,,,,,,,,,,,,,,,,,,,299.993072509766,300.0087890625,-45000.4609375,-45000.4609375,,,7.47492980957031,,1,0,0,0,0.013885498046875,31.7693061828613,1,1,1,299.993743896484,0,4232058400,300.002160644531,,,-0.0401551963474204,0.00200329445386606,-0.040157246756066,0.0020032982887453,0.976892709732056,0.979126572608948,31.4511318206787,5.60813093185425,35,4,200,-0.00184383115265518,-0.400797069072723,1.56401181221008,1,,,,,,,,,,,,,,,,
,3823633130.96607,299.995895385742,-60000.1484375,,,6,,,,31.4133701324463,,,100,,,,,,,,,,,,,,,,,,,,,,299.990478515625,300.006225585937,-60000.1484375,-60000.1484375,,,7.47114372253418,,1,0,0,0,0.013885498046875,31.7693061828613,1,1,1,299.991973876953,0,4232058304,299.999908447266,,,-0.0402306589887978,0.00200730869952394,-0.0402344578436006,0.00200731067150342,0.972018480300903,0.975582540035248,31.4653949737549,5.60940217971802,35,4,200,-0.00197311653755605,-0.417963027954102,1.56483864784241,1,,,,,,,,,,,,,,,,
,3823633189.57498,299.993743896484,-70000.3984375,,,6,,,,31.4133701324463,,,100,,,,,,,,,,,,,,,,,,,,,,299.988433837891,300.0048828125,-70000.3984375,-70000.3984375,,,7.46644401550293,,1,0,0,0,0.013885498046875,31.7693061828613,1,1,1,299.989288330078,0,4232058336,299.998046875,,,-0.040261670887831,0.00200907894108814,-0.0402674365499429,0.00200908356524275,0.968299746513367,0.973104596138001,31.4772205352783,0,35,4,200,-0.00226267566904426,-0.425656378269196,1.56241130828857,1,,,,,,,,,,,,,,,,